Workbook

Sheet Guía de uso
A1: INSTRUCCIONES DE USO
A6: Para el uso correcto de esta herramienta, usted debe: | Y6: 0 | AA6: =+CONCATENATE($A$20," ",#REF!," = ",#REF!) -> #REF!
A7: OBJETIVO | Y7: 1 | AA7: =+CONCATENATE($A$20," ",$A$21," = ",$B$21) -> Nivel 1 = Inicial
A8: Este documento tiene como objetivo servir como una guía exhaustiva y detallada para la implementación, mantenimiento y mejora continua de un Sistema de Gestión de Seguridad de la Información (SGSI). Además, facilita la evaluación del nivel de madurez del SGSI en alineación con la norma ISO 27001:2022, al proporcionar una herramienta integral que apoya a las organizaciones en la gestión eficaz y robusta de la seguridad de la información, garantizando la confidencialidad, integridad y disponibilidad de sus activos. | Y8: 2 | AA8: =+CONCATENATE($A$20," ",$A$22," = ",$B$22) -> Nivel 2 = Repetible
Y9: 3 | AA9: =+CONCATENATE($A$20," ",$A$23," = ",$B$23) -> Nivel 3 = Definido
Y10: 4 | AA10: =+CONCATENATE($A$20," ",$A$24," = ",$B$24) -> Nivel 4 = Gestionado
A11: ALCANCE | Y11: 5 | AA11: =+CONCATENATE($A$20," ",#REF!," = ",#REF!) -> #REF!
A12: Mediante el uso de una tabla de evaluación de madurez, este documento ayudará a identificar el nivel de madurez del Sistemas de gestión de seguridad de la información y proporcionará recomendaciones específicas para alcanzar niveles superiores. Esta herramienta no pretende ser exhaustiva, sino proporcionar una base sólida para el análisis y la toma de decisiones.
A13: INSTRUCCIONES DE USO
A15: Personalización de niveles de madurez
A16: En el siguiente cuadro podrá personalizar los niveles, de manera determinada visualizará del 0 al 4, y la descripción y definición correspondiente, podrá realizar la modificación de la columna de "Descripción" a adjetivos relacionados a su organización, como por ejemplo, "gestionado" por "administrado", etc.
A20: Nivel | B20: Descripción | C20: Definición
A21: 1 | B21: Inicial | C21: Los procesos de gestión de la seguridad de la información no están documentados ni formalizados. Las actividades relacionadas con la seguridad de la información se llevan a cabo de manera ad-hoc y reactiva, respondiendo a incidentes y problemas a medida que surgen sin un enfoque estructurado.
A22: 2 | B22: Repetible | C22: Los procesos de gestión de la seguridad de la información están documentados y existe un esfuerzo por seguir una metodología básica. Sin embargo, la implementación de estos procesos es inconsistente y depende en gran medida de individuos específicos.
A23: 3 | B23: Definido | C23: Los procesos de gestión de la seguridad de la información están bien documentados y definidos. La organización sigue metodologías estándar y existe un nivel básico de control y supervisión.
A24: 4 | B24: Gestionado | C24: La gestión de la seguridad de la información está bien integrada en la mayoría de los procesos de la organización. Los procesos están controlados y supervisados regularmente, utilizando métricas y KPIs para evaluar su efectividad.
A26: 1. Checklist - Contexto, liderazgo, planificación, soporte, operación, evaluación y mejora
A27: En estas hojas, en la columna "G" podrá marcar o seleccionar el nivel al cual corresponde el estado actual del cumplimiento de cada uno de los aspectos:
A28: RECUERDE: No seleccione dos niveles, ya que puede afectar el correcto funcionamiento de la herramienta y la evaluación del nivel actual
A29: Al seleccionar el nivel, de manera automática se resaltará el enunciado
A36: 2. Resumen y valoración
A37: De acuerdo con la información ingresada en las hojas de "Checklist" de cada aspecto, visualizará un resumen de cada uno de los niveles seleccionados.
A40: A continuación, visualice la estructura de esta hoja:
A52: 1. Aspectos: En esta columna visualizará el listado de los aspectos a tener en cuenta según la ISO 27001:2022
A53: 2. Nivel actual: En esta columna podrá detallar cuál fue el nivel seleccionado en cada aspecto a tener en cuenta.
A54: 2. Puntaje promedio nivel actual: En estas dos celdas visualizará el puntaje del nivel actual tanto cualitativamente como cuantitativamente respecto al promedio de las calificaciones de cada uno de los aspectos.
A55: 4. Riesgo: Seleccione en esta columna la valoración del riesgo para cada aspecto, además podrá describir el riesgo en detalle.
A58: A continuación, visualice la estructura de esta hoja:
... A69: En la última pestaña de este documento, visualizará de manera gráfica el estado actual del sistema de gestión del riesgo y seguridad en la organización, según la norma ISO 27001:2022. Esta hoja tiene como objetivo proporcionar una representación visual clara y comprensible de los resultados de la evaluación, destacando las áreas de fortaleza y las oportunidades de mejora. A través de gráficos y diagrama de telaraña, los usuarios pueden identificar rápidamente el nivel de madurez en diferentes aspectos de la gestión del riesgo, facilitando la comunicación de los resultados a las partes interesadas y apoyando la toma de decisiones estratégicas para avanzar hacia niveles superiores de madurez.
A74: De color azul | B74: visualizará el nivel óptimo, de manera predeterminada, es de 4.
A75: De color naranja | B75: visualizará el estado actual de los aspectos a evaluar según la norma ISO 27001:2022, de manera predeterminada el nivel óptimo es de 4.
A77: RECOMENDACIONES DE USO
A78: No modifique la formulación o estructura del documento. Si tiene cualquier duda o inquietud sobre su funcionamiento, lo invitamos a comunicarse por medio de nuestro correo electrónico: info@auditool.org
B81: Autor: Equipo Auditool | I81: info@auditool.org

Sheet Check - Contexto
B1: Herramienta para medir el nivel actual de los Sistemas de gestión de seguridad de la información según ISO 27001:2022
A5: Entidad (o cliente): | C5: ID. | D5: Período de auditoría de: 1/01/2023 | E5: Hasta: 31/12/2023 | G5: Referencia
A6: Preparado por: | D6: Revisado por: | G6: XX-XX
A7: Supervisado por: | D7: Aprobado por:
A10: OBJETIVO
A11: Esta herramienta permite evaluar y asegurar el estado actual de la implementación, mantenimiento y mejora del sistema de gestión de la seguridad de la información (SGSI) según la norma ISO 27001:2022, y determinar si está integrado y aplicado de manera efectiva en la organización. Esto incluye verificar que la seguridad de la información está gestionada de forma sistemática, adaptada a las necesidades organizacionales, y en mejora continua.
A12: ALCANCE
A13: El contexto de la organización es un aspecto crucial en la implementación y mantenimiento de un sistema de gestión de la seguridad de la información (SGSI) conforme a la norma ISO 27001:2022. Comprender el contexto en el que opera la organización permite identificar y gestionar eficazmente los riesgos y oportunidades relacionados con la seguridad de la información.
A14: CHECKLIST ISO 27001 - CONTEXTO DE LA ORGANIZACIÓN
A15: 1.1 Entender la organización y su contexto: Para establecer un SGSI efectivo, la organización debe identificar los problemas externos e internos que son relevantes para su propósito y que pueden afectar su capacidad para lograr los resultados esperados. Esto implica un análisis profundo de factores como el entorno económico, social, tecnológico, ambiental, legal y cultural en el que opera la organización. | G15: =IF(COUNTIF(G17:G20,TRUE)>1,"SELECCIONE SOLAMENTE UN NIVEL","Marque la opción que describa mejor la situación actual del contexto de la organización ") -> Marque la opción que describa mejor la situación actual del contexto de la organización
A16: Nivel | B16: Detalle | D16: Descripción | F16: Características
A17: =+'Guía de uso'!$AA$7 -> Nivel 1 = Inicial | B17: No se realizan esfuerzos documentados para comprender el contexto organizacional. | D17: Las actividades se llevan a cabo sin un enfoque estructurado y carecen de documentación formal. | F17: Falta de documentación. Acciones reactivas. No hay evaluación del contexto externo o interno. | G17: FALSE | J17: =+IF(G17=TRUE,'Guía de uso'!$Y$7,0) -> 0
A18: =+'Guía de uso'!$AA$8 -> Nivel 2 = Repetible | B18: Los procesos básicos están documentados, pero su aplicación es irregular y depende de individuos clave. | D18: Existen esfuerzos por documentar los procesos, pero la implementación es inconsistente y no sistemática. | F18: Documentación básica. Implementación inconsistente. Dependencia de individuos específicos para la evaluación del contexto. | G18: TRUE | J18: =+IF(G18=TRUE,'Guía de uso'!$Y$8,0) -> 2
A19: =+'Guía de uso'!$AA$9 -> Nivel 3 = Definido | B19: Se utilizan metodologías estandarizadas y los procesos están documentados y definidos. | D19: Los procesos están bien documentados y se siguen metodologías estándar, con un nivel básico de control y supervisión. | F19: Documentación clara y definida. Uso de metodologías estándar. Evaluación regular del contexto organizacional. | G19: FALSE | J19: =+IF(G19=TRUE,'Guía de uso'!$Y$9,0) -> 0
A20: =+'Guía de uso'!$AA$10 -> Nivel 4 = Gestionado | B20: El contexto organizacional se integra en los procesos, con controles y supervisión regulares mediante KPIs. | D20: La evaluación del contexto está integrada en los procesos organizacionales, con monitoreo continuo y uso de métricas y KPIs para asegurar la efectividad y mejora. | F20: Integración completa en los procesos de la organización. Control y supervisión continuos. Uso de métricas y KPIs para la evaluación y mejora continua. | G20: FALSE | J20: =+IF(G20=TRUE,'Guía de uso'!$Y$10,0) -> 0
A21: 1.2. Comprender las necesidades y expectativas de las partes interesadas: La organización debe determinar las partes interesadas que son relevantes para su SGSI, así como sus requisitos. Esto incluye no solo los requisitos legales y reglamentarios, sino también las expectativas y necesidades de clientes, proveedores, empleados y otras partes interesadas. | G21: =IF(COUNTIF(G23:G26,TRUE)>1,"SELECCIONE SOLAMENTE UN NIVEL","Marque la opción que describa mejor la situación actual del contexto de la organización ") -> Marque la opción que describa mejor la situación actual del contexto de la organización
A22: Nivel | B22: Detalle | D22: Descripción | F22: Características
A23: =+'Guía de uso'!$AA$7 -> Nivel 1 = Inicial | B23: No se identifican ni documentan las necesidades de las partes interesadas. | D23: Las actividades relacionadas con la identificación de necesidades de partes interesadas son reactivas y sin documentación formal. | F23: Ausencia de identificación de partes interesadas. Falta de documentación de necesidades. Actividades ad-hoc y reactivas. | G23: FALSE | J23: =+IF(G23=TRUE,'Guía de uso'!$Y$7,0) -> 0
A24: =+'Guía de uso'!$AA$8 -> Nivel 2 = Repetible | B24: Existen intentos documentados de identificación, pero su ejecución es inconsistente. | D24: Hay esfuerzos por identificar y documentar las necesidades de las partes interesadas, pero estos son irregulares y dependen de ciertos individuos. | F24: Intentos básicos de documentación. Ejecución irregular y dependiente de individuos específicos. Esfuerzos iniciales por identificar necesidades de partes interesadas. | G24: FALSE | J24: =+IF(G24=TRUE,'Guía de uso'!$Y$8,0) -> 0
A25: =+'Guía de uso'!$AA$9 -> Nivel 3 = Definido | B25: Procesos documentados y metodologías estándar aseguran la identificación y entendimiento adecuados. | D25: La identificación y documentación de las necesidades de las partes interesadas se realiza de manera consistente, siguiendo metodologías estándar. | F25: Procesos bien documentados. Uso de metodologías estándar para la identificación de necesidades. Evaluación y documentación regular de las expectativas de las partes interesadas. | G25: TRUE | J25: =+IF(G25=TRUE,'Guía de uso'!$Y$9,0) -> 3
A26: =+'Guía de uso'!$AA$10 -> Nivel 4 = Gestionado | B26: La identificación de necesidades está plenamente integrada, con monitoreo regular y uso de métricas. | D26: La identificación y evaluación de las necesidades de las partes interesadas está integrada en los procesos organizacionales, con monitoreo continuo y uso de KPIs. | F26: Integración completa en los procesos organizacionales. Monitoreo y control regulares. Evaluación continua mediante métricas y KPIs para asegurar la satisfacción de las partes interesadas. | G26: FALSE | J26: =+IF(G26=TRUE,'Guía de uso'!$Y$10,0) -> 0
A27: 1.3. Determinación del alcance del Sistema de Gestión de Seguridad de la Información: Definir claramente el alcance del SGSI es fundamental para su eficacia. La organización debe determinar los límites y la aplicabilidad del SGSI, considerando los factores internos y externos identificados así como los requisitos de las partes interesadas. | G27: =IF(COUNTIF(G29:G32,TRUE)>1,"SELECCIONE SOLAMENTE UN NIVEL","Marque la opción que describa mejor la situación actual del contexto de la organización ") -> Marque la opción que describa mejor la situación actual del contexto de la organización
A28: Nivel | B28: Detalle | D28: Descripción | F28: Características
A29: =+'Guía de uso'!$AA$7 -> Nivel 1 = Inicial | B29: No se determina ni formaliza el alcance del SGSI. Las actividades son reactivas y no estructuradas. | D29: No hay esfuerzos documentados para establecer el alcance del SGSI, resultando en actividades ad-hoc y sin una dirección clara. | F29: Ausencia de documentación. Actividades reactivas y no estructuradas. Falta de determinación del alcance del SGSI. | G29: FALSE | J29: =+IF(G29=TRUE,'Guía de uso'!$Y$7,0) -> 0
A30: =+'Guía de uso'!$AA$8 -> Nivel 2 = Repetible | B30: El alcance del SGSI está documentado, pero su implementación depende en gran medida de personas específicas. | D30: Existen esfuerzos para documentar el alcance del SGSI, pero la implementación es inconsistente y depende de individuos específicos. | F30: Documentación básica. Implementación irregular y dependiente de individuos específicos. Esfuerzos iniciales por determinar el alcance del SGSI. | G30: FALSE | J30: =+IF(G30=TRUE,'Guía de uso'!$Y$8,0) -> 0
A31: =+'Guía de uso'!$AA$9 -> Nivel 3 = Definido | B31: El alcance del SGSI está bien documentado y definido, siguiendo metodologías estándar. | D31: La documentación del alcance del SGSI es clara y sigue metodologías estándar, con un nivel básico de control y supervisión para asegurar su efectividad. | F31: Alcance bien definido y documentado. Uso de metodologías estándar. Evaluación y documentación regular del alcance del SGSI. | G31: TRUE | J31: =+IF(G31=TRUE,'Guía de uso'!$Y$9,0) -> 3
A32: =+'Guía de uso'!$AA$10 -> Nivel 4 = Gestionado | B32: El alcance del SGSI está completamente integrado y supervisado regularmente con métricas y KPIs. | D32: La determinación del alcance del SGSI está integrada en los procesos organizacionales, con monitoreo continuo y uso de métricas y KPIs para asegurar la efectividad. | F32: Integración completa en los procesos de la organización. Control y supervisión continuos. Uso de métricas y KPIs para la evaluación y mejora continua del alcance del SGSI. | G32: FALSE | J32: =+IF(G32=TRUE,'Guía de uso'!$Y$10,0) -> 0
A33: 1.4. Sistema de Gestión de Seguridad de la Información: Una vez definido el contexto y el alcance, la organización debe establecer, implementar, mantener y mejorar continuamente un SGSI que incluya los procesos necesarios y sus interacciones. Esto garantiza que el SGSI esté plenamente integrado en las operaciones de la organización y que pueda adaptarse a los cambios en el contexto interno y externo. | G33: =IF(COUNTIF(G35:G38,TRUE)>1,"SELECCIONE SOLAMENTE UN NIVEL","Marque la opción que describa mejor la situación actual del contexto de la organización ") -> Marque la opción que describa mejor la situación actual del contexto de la organización
A34: Nivel | B34: Detalle | D34: Descripción | F34: Características
A35: =+'Guía de uso'!$AA$7 -> Nivel 1 = Inicial | B35: No existe un SGSI documentado; las acciones son reactivas y no estructuradas. | C35: No existe un SGSI documentado; las acciones son reactivas y no estructuradas. | D35: Las actividades relacionadas con el SGSI son ad-hoc y no documentadas, resultando en una gestión desorganizada y reactiva. | F35: Ausencia de documentación del SGSI. Actividades reactivas y no estructuradas. Falta de dirección clara en la gestión de la seguridad de la información. | G35: FALSE | J35: =+IF(G35=TRUE,'Guía de uso'!$Y$7,0) -> 0
A36: =+'Guía de uso'!$AA$8 -> Nivel 2 = Repetible | B36: El SGSI está documentado, pero su aplicación es inconsistente y varía según el individuo. | C36: El SGSI está documentado, pero su aplicación es inconsistente y varía según el individuo. | D36: Existen esfuerzos por documentar el SGSI, pero la implementación es inconsistente y depende en gran medida de individuos específicos para su aplicación efectiva. | F36: Documentación básica del SGSI. Implementación irregular y dependiente de individuos específicos. Esfuerzos iniciales por formalizar el SGSI. | G36: TRUE | J36: =+IF(G36=TRUE,'Guía de uso'!$Y$8,0) -> 2
A37: =+'Guía de uso'!$AA$9 -> Nivel 3 = Definido | B37: SGSI bien definido y documentado, con control y supervisión básica siguiendo metodologías estándar. | C37: SGSI bien definido y documentado, con control y supervisión básica siguiendo metodologías estándar. | D37: La documentación y definición del SGSI es clara, siguiendo metodologías estándar con un nivel básico de control y supervisión para asegurar la efectividad. | F37: SGSI bien definido y documentado. Uso de metodologías estándar. Control y supervisión básica del SGSI. | G37: FALSE | J37: =+IF(G37=TRUE,'Guía de uso'!$Y$9,0) -> 0
A38: =+'Guía de uso'!$AA$10 -> Nivel 4 = Gestionado | B38: El SGSI está completamente integrado en los procesos, con controles, supervisión regular y evaluación con KPIs. | C38: El SGSI está completamente integrado en los procesos, con controles, supervisión regular y evaluación con KPIs. | D38: La gestión del SGSI está integrada en los procesos organizacionales, con monitoreo continuo y uso de métricas y KPIs para asegurar la efectividad y mejora continua. | F38: Integración completa del SGSI en los procesos de la organización. Control y supervisión continuos. Uso de métricas y KPIs para la evaluación y mejora continua del SGSI. | G38: FALSE | J38: =+IF(G38=TRUE,'Guía de uso'!$Y$10,0) -> 0
A40: CONCLUSIÓN Y/O OBSERVACIONES ADICIONALES

Sheet Check - Liderazgo
B1: Herramienta para medir el nivel actual de los Sistemas de gestión de seguridad de la información según ISO 27001:2022
A5: Entidad (o cliente): | C5: ID. | D5: Período de auditoría de: 1/01/2023 | E5: Hasta: 31/12/2023 | G5: Referencia
A6: Preparado por: | D6: Revisado por: | G6: XX-XX
A7: Supervisado por: | D7: Aprobado por:
A10: OBJETIVO
A11: Esta herramienta permite evaluar y asegurar el estado actual de la implementación, mantenimiento y mejora del sistema de gestión de la seguridad de la información (SGSI) según la norma ISO 27001:2022, y determinar si está integrado y aplicado de manera efectiva en la organización. Esto incluye verificar que la seguridad de la información está gestionada de forma sistemática, adaptada a las necesidades organizacionales, y en mejora continua.
A12: ALCANCE
A13: El liderazgo es un componente esencial para el éxito de un sistema de gestión de la seguridad de la información (SGSI) según la norma ISO 27001:2022. La alta dirección tiene la responsabilidad de establecer una visión clara y un compromiso firme con la seguridad de la información, asegurando que esté integrada en todos los niveles de la organización.
A14: CHECKLIST ISO 27001 - LIDERAZGO
A15: 2.1 Liderazgo y compromiso: La alta dirección debe demostrar liderazgo y compromiso con respecto al SGSI mediante diversas acciones. Estas incluyen garantizar que la política de seguridad de la información y los objetivos asociados estén alineados con la dirección estratégica de la organización, y que los requisitos del SGSI se integren en los procesos de la organización. | G15: =IF(COUNTIF(G17:G20,TRUE)>1,"SELECCIONE SOLAMENTE UN NIVEL","Marque la opción que describa mejor la situación actual del liderazgo") -> Marque la opción que describa mejor la situación actual del liderazgo
A16: Nivel | B16: Detalle | D16: Descripción | F16: Características
A17: =+'Guía de uso'!$AA$7 -> Nivel 1 = Inicial | B17: La alta dirección no demuestra un compromiso formalizado con el SGSI. | D17: No hay evidencia de un compromiso estructurado por parte de la alta dirección para apoyar y liderar el SGSI. | F17: Ausencia de compromiso formalizado. Falta de liderazgo claro en seguridad de la información. Actividades reactivas y no estructuradas. | G17: FALSE | J17: =+IF(G17=TRUE,'Guía de uso'!$Y$7,0) -> 0
A18: =+'Guía de uso'!$AA$8 -> Nivel 2 = Repetible | B18: La alta dirección muestra un compromiso básico y existen esfuerzos documentados, aunque irregulares. | D18: Existen esfuerzos documentados para demostrar el compromiso de la alta dirección, pero la aplicación es inconsistente. | F18: Compromiso básico documentado. Implementación irregular. Dependencia de individuos específicos para liderar las iniciativas de seguridad. | G18: TRUE | J18: =+IF(G18=TRUE,'Guía de uso'!$Y$8,0) -> 2
A19: =+'Guía de uso'!$AA$9 -> Nivel 3 = Definido | B19: El compromiso de la alta dirección está bien documentado y sigue metodologías estándar con control básico. | D19: La alta dirección demuestra un compromiso claro y documentado, siguiendo metodologías estándar y asegurando un nivel básico de control y supervisión. | F19: Compromiso claro y documentado. Uso de metodologías estándar. Control y supervisión básica del compromiso de la alta dirección. | G19: FALSE | J19: =+IF(G19=TRUE,'Guía de uso'!$Y$9,0) -> 0
A20: =+'Guía de uso'!$AA$10 -> Nivel 4 = Gestionado | B20: El compromiso de la alta dirección está completamente integrado, con supervisión regular y uso de métricas para evaluar su efectividad. | D20: La alta dirección está plenamente integrada en los procesos de seguridad, con monitoreo continuo y uso de métricas y KPIs para evaluar y mejorar su compromiso. | F20: Integración completa del compromiso de la alta dirección en los procesos. Supervisión y control regulares. Uso de métricas y KPIs para evaluar el compromiso. | G20: FALSE | J20: =+IF(G20=TRUE,'Guía de uso'!$Y$10,0) -> 0
A21: 2.2 Política: La alta dirección debe establecer una política de seguridad de la información que sea apropiada para el propósito de la organización y que incluya objetivos claros. Esta política debe reflejar el compromiso de la organización de cumplir con los requisitos aplicables y de mejorar continuamente el SGSI. | G21: =IF(COUNTIF(G23:G26,TRUE)>1,"SELECCIONE SOLAMENTE UN NIVEL","Marque la opción que describa mejor la situación actual del liderazgo") -> Marque la opción que describa mejor la situación actual del liderazgo
A22: Nivel | B22: Detalle | D22: Descripción | F22: Características
A23: =+'Guía de uso'!$AA$7 -> Nivel 1 = Inicial | B23: No se ha establecido una política de seguridad de la información formalizada. | D23: Las actividades de seguridad se realizan sin una política definida, resultando en una falta de dirección clara y coherencia en las acciones de seguridad. | F23: Ausencia de política formal. Actividades de seguridad sin dirección clara. Falta de coherencia en las acciones de seguridad. | G23: FALSE | J23: =+IF(G23=TRUE,'Guía de uso'!$Y$7,0) -> 0
A24: =+'Guía de uso'!$AA$8 -> Nivel 2 = Repetible | B24: Existe una política básica de seguridad de la información, pero su implementación es inconsistente. | D24: Se ha establecido una política de seguridad, pero la aplicación y el seguimiento son irregulares y dependen de individuos específicos. | F24: Política básica documentada. Implementación irregular. Dependencia de individuos específicos para aplicar y seguir la política. | G24: FALSE | J24: =+IF(G24=TRUE,'Guía de uso'!$Y$8,0) -> 0
A25: =+'Guía de uso'!$AA$9 -> Nivel 3 = Definido | B25: La política de seguridad está bien documentada y definida, siguiendo metodologías estándar con control y supervisión básicos. | D25: La política de seguridad está claramente documentada, siguiendo metodologías estándar, con un nivel básico de control y supervisión para asegurar su aplicación. | F25: Política bien definida y documentada. Uso de metodologías estándar. Control y supervisión básicos de la aplicación de la política. | G25: TRUE | J25: =+IF(G25=TRUE,'Guía de uso'!$Y$9,0) -> 3
A26: =+'Guía de uso'!$AA$10 -> Nivel 4 = Gestionado | B26: La política de seguridad está completamente integrada en los procesos, con supervisión regular y uso de métricas para evaluar su efectividad. | D26: La política de seguridad está integrada en los procesos organizacionales, con monitoreo continuo y uso de métricas y KPIs para asegurar su efectividad y mejora. | F26: Integración completa de la política en los procesos. Supervisión y control regulares. Uso de métricas y KPIs para evaluar la efectividad de la política. | G26: FALSE | J26: =+IF(G26=TRUE,'Guía de uso'!$Y$10,0) -> 0
A27: 2.3 Funciones, responsabilidades y autoridades de la organización: La alta dirección debe asegurarse de que las responsabilidades y autoridades para los roles relevantes en la seguridad de la información se asignen y comuniquen claramente dentro de la organización. Esto incluye asignar la responsabilidad y autoridad para garantizar que el SGSI cumpla con los requisitos de la norma ISO 27001 y para informar sobre el desempeño del SGSI a la alta dirección. | G27: =IF(COUNTIF(G29:G32,TRUE)>1,"SELECCIONE SOLAMENTE UN NIVEL","Marque la opción que describa mejor la situación actual del liderazgo") -> Marque la opción que describa mejor la situación actual del liderazgo
A28: Nivel | B28: Detalle | D28: Descripción | F28: Características
A29: =+'Guía de uso'!$AA$7 -> Nivel 1 = Inicial | B29: No se han definido ni documentado las funciones, responsabilidades y autoridades relacionadas con la seguridad de la información. | D29: Las actividades se llevan a cabo sin roles y responsabilidades claramente definidos, lo que provoca confusión y falta de responsabilidad en las acciones de seguridad. | F29: Ausencia de roles y responsabilidades definidos. Actividades sin dirección clara. Falta de responsabilidad en las acciones de seguridad. | G29: FALSE | J29: =+IF(G29=TRUE,'Guía de uso'!$Y$7,0) -> 0
A30: =+'Guía de uso'!$AA$8 -> Nivel 2 = Repetible | B30: Existen definiciones básicas de roles y responsabilidades, pero su implementación es inconsistente. | D30: Se han definido y documentado roles y responsabilidades básicas, pero su aplicación es irregular y depende de individuos específicos. | F30: Definición básica de roles y responsabilidades. Implementación irregular. Dependencia de individuos específicos para aplicar y seguir las definiciones. | G30: TRUE | J30: =+IF(G30=TRUE,'Guía de uso'!$Y$8,0) -> 2
A31: =+'Guía de uso'!$AA$9 -> Nivel 3 = Definido | B31: Las funciones, responsabilidades y autoridades están bien documentadas y definidas, siguiendo metodologías estándar con control básico. | D31: Las funciones y responsabilidades están claramente documentadas, siguiendo metodologías estándar, con un nivel básico de control y supervisión para asegurar su efectividad. | F31: Definición clara y documentada de roles y responsabilidades. Uso de metodologías estándar. Control y supervisión básica de la aplicación de las funciones. | G31: FALSE | J31: =+IF(G31=TRUE,'Guía de uso'!$Y$9,0) -> 0
A32: =+'Guía de uso'!$AA$10 -> Nivel 4 = Gestionado | B32: Las funciones, responsabilidades y autoridades están completamente integradas en los procesos, con supervisión regular y uso de métricas para evaluar su efectividad. | D32: Las funciones y responsabilidades están integradas en los procesos organizacionales, con monitoreo continuo y uso de métricas y KPIs para asegurar su efectividad y mejora continua. | F32: Integración completa de las funciones en los procesos. Supervisión y control regulares. Uso de métricas y KPIs para evaluar la efectividad de las funciones. | G32: FALSE | J32: =+IF(G32=TRUE,'Guía de uso'!$Y$10,0) -> 0
A34: CONCLUSIÓN Y/O OBSERVACIONES ADICIONALES

Sheet Check - Planificación
B1: Herramienta para medir el nivel actual de los Sistemas de gestión de seguridad de la información según ISO 27001:2022
A5: Entidad (o cliente): | C5: ID. | D5: Período de auditoría de: 1/01/2023 | E5: Hasta: 31/12/2023 | G5: Referencia
A6: Preparado por: | D6: Revisado por: | G6: XX-XX
A7: Supervisado por: | D7: Aprobado por:
A10: OBJETIVO
A11: Esta herramienta permite evaluar y asegurar el estado actual de la implementación, mantenimiento y mejora del sistema de gestión de la seguridad de la información (SGSI) según la norma ISO 27001:2022, y determinar si está integrado y aplicado de manera efectiva en la organización. Esto incluye verificar que la seguridad de la información está gestionada de forma sistemática, adaptada a las necesidades organizacionales, y en mejora continua.
A12: ALCANCE
A13: La planificación es un componente crítico del sistema de gestión de la seguridad de la información (SGSI) según la norma ISO 27001:2022. Un enfoque sistemático de la planificación asegura que los riesgos y oportunidades relacionados con la seguridad de la información sean identificados y gestionados adecuadamente. Esto permite a la organización establecer objetivos claros y formular estrategias para alcanzarlos, garantizando así la protección continua de la información.
A14: CHECKLIST ISO 27001 - PLANIFICACIÓN
A15: 3.1. Acciones para abordar riesgos y oportunidades: La organización debe planificar las acciones necesarias para abordar los riesgos y oportunidades que pueden afectar la capacidad del SGSI para lograr los resultados previstos. Esto incluye garantizar que el SGSI pueda alcanzar sus objetivos, prevenir o reducir efectos no deseados y fomentar la mejora continua. La planificación debe integrar estas acciones en los procesos del SGSI y evaluar su efectividad. | G15: =IF(COUNTIF(G17:G20,TRUE)>1,"SELECCIONE SOLAMENTE UN NIVEL","Marque la opción que describa mejor la situación actual del proceso de planificación") -> Marque la opción que describa mejor la situación actual del proceso de planificación
A16: Nivel | B16: Detalle | D16: Descripción | F16: Características
A17: =+'Guía de uso'!$AA$7 -> Nivel 1 = Inicial | B17: No se toman acciones formales para abordar riesgos y oportunidades. | D17: Las acciones relacionadas con riesgos y oportunidades son ad-hoc y no estructuradas, sin documentación formal ni seguimiento sistemático. | F17: Ausencia de acciones formales. Actividades reactivas y no estructuradas. Falta de documentación y seguimiento. | G17: FALSE | J17: =+IF(G17=TRUE,'Guía de uso'!$Y$7,0) -> 0
A18: =+'Guía de uso'!$AA$8 -> Nivel 2 = Repetible | B18: Existen esfuerzos básicos documentados para abordar riesgos y oportunidades, pero su implementación es inconsistente. | D18: Se han documentado acciones para abordar riesgos y oportunidades, pero la implementación depende de individuos específicos y no es sistemática. | F18: Documentación básica de acciones. Implementación irregular. Dependencia de individuos específicos. | G18: TRUE | J18: =+IF(G18=TRUE,'Guía de uso'!$Y$8,0) -> 2
A19: =+'Guía de uso'!$AA$9 -> Nivel 3 = Definido | B19: Las acciones para abordar riesgos y oportunidades están bien documentadas y siguen metodologías estándar con control básico. | D19: Las acciones están claramente documentadas, siguiendo metodologías estándar, con un nivel básico de control y supervisión para asegurar su efectividad. | F19: Documentación clara y definida de acciones. Uso de metodologías estándar. Control y supervisión básicos. | G19: FALSE | J19: =+IF(G19=TRUE,'Guía de uso'!$Y$9,0) -> 0
A20: =+'Guía de uso'!$AA$10 -> Nivel 4 = Gestionado | B20: Las acciones para abordar riesgos y oportunidades están completamente integradas en los procesos, con supervisión regular y métricas de evaluación. | D20: Las acciones están integradas en los procesos organizacionales, con monitoreo continuo y uso de métricas y KPIs para asegurar la efectividad y mejora. | F20: Integración completa en los procesos. Supervisión y control regulares. Uso de métricas y KPIs para evaluar la efectividad de las acciones. | G20: FALSE | J20: =+IF(G20=TRUE,'Guía de uso'!$Y$10,0) -> 0
A21: 3.2 Objetivos de Seguridad de la Información y planificación para alcanzarlos: La organización debe establecer objetivos de seguridad de la información en las funciones y niveles pertinentes. Estos objetivos deben ser coherentes con la política de seguridad de la información, medibles, monitoreados, comunicados y actualizados según corresponda. La planificación para alcanzar estos objetivos debe incluir la determinación de las acciones necesarias, los recursos requeridos, las responsabilidades asignadas, los plazos y los métodos para evaluar los resultados. | G21: =IF(COUNTIF(G23:G26,TRUE)>1,"SELECCIONE SOLAMENTE UN NIVEL","Marque la opción que describa mejor la situación actual del proceso de planificación") -> Marque la opción que describa mejor la situación actual del proceso de planificación
A22: Nivel | B22: Detalle | D22: Descripción | F22: Características
A23: =+'Guía de uso'!$AA$7 -> Nivel 1 = Inicial | B23: No se han establecido ni documentado objetivos de seguridad de la información. | D23: Las actividades de seguridad se realizan sin objetivos claros, lo que resulta en una falta de dirección y coherencia en las acciones de seguridad. | F23: Ausencia de objetivos formales. Actividades de seguridad sin dirección clara. Falta de coherencia en las acciones de seguridad. | G23: FALSE | J23: =+IF(G23=TRUE,'Guía de uso'!$Y$7,0) -> 0
A24: =+'Guía de uso'!$AA$8 -> Nivel 2 = Repetible | B24: Existen objetivos básicos de seguridad de la información, pero su implementación y seguimiento son inconsistentes. | D24: Se han establecido y documentado objetivos, pero la implementación y el seguimiento dependen de individuos específicos y no son sistemáticos. | F24: Objetivos básicos documentados. Implementación y seguimiento irregulares. Dependencia de individuos específicos. | G24: TRUE | J24: =+IF(G24=TRUE,'Guía de uso'!$Y$8,0) -> 2
A25: =+'Guía de uso'!$AA$9 -> Nivel 3 = Definido | B25: Los objetivos de seguridad están bien documentados y definidos, siguiendo metodologías estándar con control y supervisión básicos. | D25: Los objetivos de seguridad están claramente documentados y definidos, siguiendo metodologías estándar, con un nivel básico de control y supervisión para asegurar su efectividad. | F25: Objetivos bien definidos y documentados. Uso de metodologías estándar. Control y supervisión básicos. | G25: FALSE | J25: =+IF(G25=TRUE,'Guía de uso'!$Y$9,0) -> 0
A26: =+'Guía de uso'!$AA$10 -> Nivel 4 = Gestionado | B26: Los objetivos de seguridad están completamente integrados en los procesos, con supervisión regular y uso de métricas para evaluar su efectividad. | D26: Los objetivos de seguridad están integrados en los procesos organizacionales, con monitoreo continuo y uso de métricas y KPIs para asegurar la efectividad y mejora. | F26: Integración completa de los objetivos en los procesos. Supervisión y control regulares. Uso de métricas y KPIs para evaluar la efectividad de los objetivos. | G26: FALSE | J26: =+IF(G26=TRUE,'Guía de uso'!$Y$10,0) -> 0
A28: CONCLUSIÓN Y/O OBSERVACIONES ADICIONALES

Sheet Check - Soporte
B1: Herramienta para medir el nivel actual de los Sistemas de gestión de seguridad de la información según ISO 27001:2022
A5: Entidad (o cliente): | C5: ID. | D5: Período de auditoría de: 1/01/2023 | E5: Hasta: 31/12/2023 | G5: Referencia
A6: Preparado por: | D6: Revisado por: | G6: XX-XX
A7: Supervisado por: | D7: Aprobado por:
A10: OBJETIVO
A11: Esta herramienta permite evaluar y asegurar el estado actual de la implementación, mantenimiento y mejora del sistema de gestión de la seguridad de la información (SGSI) según la norma ISO 27001:2022, y determinar si está integrado y aplicado de manera efectiva en la organización. Esto incluye verificar que la seguridad de la información está gestionada de forma sistemática, adaptada a las necesidades organizacionales, y en mejora continua.
A12: ALCANCE
A13: El soporte es un pilar fundamental para la implementación y mantenimiento eficaz de un sistema de gestión de la seguridad de la información (SGSI) según la norma ISO 27001:2022. Este aspecto abarca todos los recursos necesarios, desde la competencia del personal hasta la gestión de la información documentada, asegurando que el SGSI funcione de manera eficiente y alcance sus objetivos de protección de la información.
A14: CHECKLIST ISO 27001 - SOPORTE
A15: 4.1 Recursos: Para que el SGSI sea efectivo, la organización debe determinar y proporcionar los recursos necesarios para su establecimiento, implementación, mantenimiento y mejora continua. Estos recursos incluyen personal, infraestructura, entorno de trabajo, recursos financieros y tecnológicos. | G15: =IF(COUNTIF(G17:G20,TRUE)>1,"SELECCIONE SOLAMENTE UN NIVEL","Marque la opción que describa mejor la situación actual del soporte ") -> Marque la opción que describa mejor la situación actual del soporte
A16: Nivel | B16: Detalle | D16: Descripción | F16: Características
A17: =+'Guía de uso'!$AA$7 -> Nivel 1 = Inicial | B17: No se asignan recursos específicos para la gestión de la seguridad de la información. | D17: Los recursos necesarios para la seguridad de la información no están definidos ni proporcionados, lo que resulta en una gestión ineficaz y reactiva. | F17: Falta de asignación de recursos. Actividades reactivas y no planificadas. | G17: FALSE | J17: =+IF(G17=TRUE,'Guía de uso'!$Y$7,0) -> 0
A18: =+'Guía de uso'!$AA$8 -> Nivel 2 = Repetible | B18: Se asignan recursos básicos, pero de manera inconsistente y dependiente de personas específicas. | D18: Hay esfuerzos por asignar recursos, pero estos son insuficientes y su asignación es irregular, dependiendo en gran medida de individuos específicos. | F18: Asignación básica e irregular de recursos. Dependencia de individuos específicos. | G18: FALSE | J18: =+IF(G18=TRUE,'Guía de uso'!$Y$8,0) -> 0
A19: =+'Guía de uso'!$AA$9 -> Nivel 3 = Definido | B19: Los recursos están bien definidos y asignados, siguiendo metodologías estándar con control básico. | D19: Los recursos necesarios para la seguridad de la información están claramente definidos y asignados, siguiendo metodologías estándar, con un nivel básico de control. | F19: Definición clara y asignación de recursos. Uso de metodologías estándar. Control y supervisión básicos de la asignación de recursos. | G19: TRUE | J19: =+IF(G19=TRUE,'Guía de uso'!$Y$9,0) -> 3
A20: =+'Guía de uso'!$AA$10 -> Nivel 4 = Gestionado | B20: Los recursos están completamente integrados en los procesos, con supervisión regular y uso de métricas para evaluar su suficiencia. | D20: La asignación de recursos está completamente integrada en los procesos organizacionales, con monitoreo continuo y uso de métricas y KPIs para evaluar su efectividad. | F20: Integración completa de la asignación de recursos en los procesos. Supervisión y control regulares. Uso de métricas y KPIs para evaluar la suficiencia de los recursos. | G20: FALSE | J20: =+IF(G20=TRUE,'Guía de uso'!$Y$10,0) -> 0
A21: 4.2. Competencia: La organización debe identificar la competencia necesaria para las personas que realizan trabajos bajo su control que afectan el desempeño de la seguridad de la información. Esto implica garantizar que estas personas sean competentes con base a una educación, formación o experiencia adecuada. Además, la organización debe tomar acciones para adquirir la competencia necesaria y evaluar la efectividad de estas acciones. | G21: =IF(COUNTIF(G23:G26,TRUE)>1,"SELECCIONE SOLAMENTE UN NIVEL","Marque la opción que describa mejor la situación actual del soporte ") -> Marque la opción que describa mejor la situación actual del soporte
A22: Nivel | B22: Detalle | D22: Descripción | F22: Características
A23: =+'Guía de uso'!$AA$7 -> Nivel 1 = Inicial | B23: No se evalúa ni se asegura la competencia del personal en materia de seguridad de la información. | D23: No existen procedimientos formales para evaluar y asegurar la competencia del personal, resultando en una falta de habilidades adecuadas para la seguridad. | F23: Ausencia de evaluación de competencias. Falta de habilidades adecuadas en seguridad de la información. | G23: FALSE | J23: =+IF(G23=TRUE,'Guía de uso'!$Y$7,0) -> 0
A24: =+'Guía de uso'!$AA$8 -> Nivel 2 = Repetible | B24: Se realizan esfuerzos básicos para evaluar la competencia, pero de manera inconsistente y dependiente de individuos específicos. | D24: Hay intentos por asegurar la competencia del personal, pero estos esfuerzos son irregulares y dependen de individuos específicos. | F24: Evaluación básica e irregular de competencias. Dependencia de individuos específicos. | G24: FALSE | J24: =+IF(G24=TRUE,'Guía de uso'!$Y$8,0) -> 0
A25: =+'Guía de uso'!$AA$9 -> Nivel 3 = Definido | B25: La competencia del personal está bien definida y evaluada, siguiendo metodologías estándar con control básico. | D25: Los requisitos de competencia están claramente definidos y se evalúan siguiendo metodologías estándar, con un nivel básico de control y supervisión. | F25: Definición clara y evaluación de competencias. Uso de metodologías estándar. Control y supervisión básicos de la competencia del personal. | G25: TRUE | J25: =+IF(G25=TRUE,'Guía de uso'!$Y$9,0) -> 3
A26: =+'Guía de uso'!$AA$10 -> Nivel 4 = Gestionado | B26: La competencia está completamente integrada en los procesos, con supervisión regular y uso de métricas para evaluar su efectividad. | D26: La competencia del personal está completamente integrada en los procesos organizacionales, con monitoreo continuo y uso de métricas y KPIs para asegurar la efectividad. | F26: Integración completa de la competencia en los procesos. Supervisión y control regulares. Uso de métricas y KPIs para evaluar la efectividad de la competencia. | G26: FALSE | J26: =+IF(G26=TRUE,'Guía de uso'!$Y$10,0) -> 0
A27: 4.3. Conciencia: El personal que realiza trabajos bajo el control de la organización debe ser consciente de la política de seguridad de la información, su contribución a la eficacia del SGSI y las implicaciones de no cumplir con los requisitos del SGSI. Asegurar la conciencia del personal es crucial para crear una cultura de seguridad de la información en toda la organización, donde cada individuo entiende su papel y responsabilidad en la protección de la información. | G27: =IF(COUNTIF(G29:G32,TRUE)>1,"SELECCIONE SOLAMENTE UN NIVEL","Marque la opción que describa mejor la situación actual del soporte ") -> Marque la opción que describa mejor la situación actual del soporte
A28: Nivel | B28: Detalle | D28: Descripción | F28: Características
A29: =+'Guía de uso'!$AA$7 -> Nivel 1 = Inicial | B29: No se realizan actividades formales para concienciar al personal sobre la seguridad de la información. | D29: Las actividades de concienciación son esporádicas y no están documentadas, resultando en una falta de entendimiento y compromiso del personal con la seguridad. | F29: Ausencia de actividades formales de concienciación. Falta de entendimiento y compromiso del personal. | G29: FALSE | J29: =+IF(G29=TRUE,'Guía de uso'!$Y$7,0) -> 0
A30: =+'Guía de uso'!$AA$8 -> Nivel 2 = Repetible | B30: Se realizan esfuerzos básicos de concienciación, pero de manera inconsistente y dependiente de individuos específicos. | D30: Hay intentos por concienciar al personal sobre la seguridad, pero estos esfuerzos son irregulares y dependen de individuos específicos. | F30: Esfuerzos básicos e irregulares de concienciación. Dependencia de individuos específicos. | G30: TRUE | J30: =+IF(G30=TRUE,'Guía de uso'!$Y$8,0) -> 2
A31: =+'Guía de uso'!$AA$9 -> Nivel 3 = Definido | B31: La concienciación sobre seguridad está bien documentada y definida, siguiendo metodologías estándar con control básico. | D31: Las actividades de concienciación están claramente documentadas y definidas, siguiendo metodologías estándar, con un nivel básico de control y supervisión. | F31: Documentación y definición claras de las actividades de concienciación. Uso de metodologías estándar. Control y supervisión básicos de la concienciación. | G31: FALSE | J31: =+IF(G31=TRUE,'Guía de uso'!$Y$9,0) -> 0
A32: =+'Guía de uso'!$AA$10 -> Nivel 4 = Gestionado | B32: La concienciación está completamente integrada en los procesos, con supervisión regular y uso de métricas para evaluar su efectividad. | D32: La concienciación sobre seguridad está completamente integrada en los procesos organizacionales, con monitoreo continuo y uso de métricas y KPIs para asegurar la efectividad. | F32: Integración completa de la concienciación en los procesos. Supervisión y control regulares. Uso de métricas y KPIs para evaluar la efectividad de la concienciación. | G32: FALSE | J32: =+IF(G32=TRUE,'Guía de uso'!$Y$10,0) -> 0
A33: 4.4. Comunicación: La organización debe determinar la necesidad de comunicaciones internas y externas relevantes para el SGSI. Esto incluye decidir sobre qué comunicar, cuándo comunicar, con quién comunicarse y cómo comunicarse. La comunicación efectiva asegura que todos los interesados, tanto internos como externos, estén informados sobre los aspectos relevantes de la seguridad de la información, facilitando la cooperación y la alineación de objetivos. | G33: =IF(COUNTIF(G35:G38,TRUE)>1,"SELECCIONE SOLAMENTE UN NIVEL","Marque la opción que describa mejor la situación actual del soporte ") -> Marque la opción que describa mejor la situación actual del soporte
A34: Nivel | B34: Detalle | D34: Descripción | F34: Características
A35: =+'Guía de uso'!$AA$7 -> Nivel 1 = Inicial | B35: No se establecen ni documentan procedimientos formales de comunicación sobre seguridad de la información. | D35: Las actividades de comunicación son ad-hoc y no están documentadas, lo que provoca una falta de coordinación y coherencia en la seguridad de la información. | F35: Ausencia de procedimientos formales de comunicación. Falta de coordinación y coherencia en las comunicaciones. | G35: FALSE | J35: =+IF(G35=TRUE,'Guía de uso'!$Y$7,0) -> 0
A36: =+'Guía de uso'!$AA$8 -> Nivel 2 = Repetible | B36: Existen procedimientos básicos de comunicación, pero su implementación es inconsistente y depende de individuos específicos. | D36: Se han establecido procedimientos para la comunicación, pero su implementación y seguimiento son irregulares y dependen de individuos específicos. | F36: Procedimientos básicos de comunicación. Implementación irregular. Dependencia de individuos específicos. | G36: FALSE | J36: =+IF(G36=TRUE,'Guía de uso'!$Y$8,0) -> 0
A37: =+'Guía de uso'!$AA$9 -> Nivel 3 = Definido | B37: Los procedimientos de comunicación están bien documentados y definidos, siguiendo metodologías estándar con control básico. | D37: Los procedimientos de comunicación están claramente documentados y definidos, siguiendo metodologías estándar, con un nivel básico de control y supervisión. | F37: Documentación y definición claras de los procedimientos de comunicación. Uso de metodologías estándar. Control y supervisión básicos de la comunicación. | G37: TRUE | J37: =+IF(G37=TRUE,'Guía de uso'!$Y$9,0) -> 3
A38: =+'Guía de uso'!$AA$10 -> Nivel 4 = Gestionado | B38: La comunicación está completamente integrada en los procesos, con supervisión regular y uso de métricas para evaluar su efectividad. | D38: La comunicación sobre seguridad está completamente integrada en los procesos organizacionales, con monitoreo continuo y uso de métricas y KPIs para asegurar la efectividad. | F38: Integración completa de la comunicación en los procesos. Supervisión y control regulares. Uso de métricas y KPIs para evaluar la efectividad de la comunicación. | G38: FALSE | J38: =+IF(G38=TRUE,'Guía de uso'!$Y$10,0) -> 0
A39: 4.5. Información documentada: La gestión de la información documentada es un componente clave del SGSI. La organización debe garantizar que se mantenga la información documentada requerida por la norma ISO 27001 y cualquier información adicional que la organización considere necesaria para la eficacia del SGSI. Esto incluye la creación y actualización de documentos, asegurando su identificación, formato y revisión adecuados. | G39: =IF(COUNTIF(G41:G44,TRUE)>1,"SELECCIONE SOLAMENTE UN NIVEL","Marque la opción que describa mejor la situación actual del soporte ") -> Marque la opción que describa mejor la situación actual del soporte
A40: Nivel | B40: Detalle | D40: Descripción | F40: Características
A41: =+'Guía de uso'!$AA$7 -> Nivel 1 = Inicial | B41: No se gestiona ni se controla formalmente la información documentada. | D41: Las actividades de documentación son esporádicas y no están formalizadas, resultando en una falta de control y coherencia en la gestión de la información. | F41: Ausencia de gestión formal de la documentación. Falta de control y coherencia en la documentación. | G41: FALSE | J41: =+IF(G41=TRUE,'Guía de uso'!$Y$7,0) -> 0
A42: =+'Guía de uso'!$AA$8 -> Nivel 2 = Repetible | B42: Existen esfuerzos básicos para gestionar la información documentada, pero de manera inconsistente y dependiente de individuos específicos. | D42: Se han establecido procedimientos básicos para la gestión de la información, pero su implementación es irregular y depende de individuos específicos. | F42: Esfuerzos básicos e irregulares de gestión de la información. Dependencia de individuos específicos. | G42: TRUE | J42: =+IF(G42=TRUE,'Guía de uso'!$Y$8,0) -> 2
A43: =+'Guía de uso'!$AA$9 -> Nivel 3 = Definido | B43: Los procedimientos para gestionar la información están bien documentados y definidos, siguiendo metodologías estándar con control básico. | D43: Los procedimientos para gestionar la información están claramente documentados y definidos, siguiendo metodologías estándar, con un nivel básico de control y supervisión. | F43: Documentación y definición claras de los procedimientos de gestión. Uso de metodologías estándar. Control y supervisión básicos de la documentación. | G43: FALSE | J43: =+IF(G43=TRUE,'Guía de uso'!$Y$9,0) -> 0
A44: =+'Guía de uso'!$AA$10 -> Nivel 4 = Gestionado | B44: La gestión de la información está completamente integrada en los procesos, con supervisión regular y uso de métricas para evaluar su efectividad. | D44: La gestión de la información está completamente integrada en los procesos organizacionales, con monitoreo continuo y uso de métricas y KPIs para asegurar la efectividad. | F44: Integración completa de la gestión de la información en los procesos. Supervisión y control regulares. Uso de métricas y KPIs para evaluar la efectividad de la gestión de la información. | G44: FALSE | J44: =+IF(G44=TRUE,'Guía de uso'!$Y$10,0) -> 0
A46: CONCLUSIÓN Y/O OBSERVACIONES ADICIONALES

Sheet Check - Operación
B1: Herramienta para medir el nivel actual de los Sistemas de gestión de seguridad de la información según ISO 27001:2022
A5: Entidad (o cliente): | C5: ID. | D5: Período de auditoría de: 1/01/2023 | E5: Hasta: 31/12/2023 | G5: Referencia
A6: Preparado por: | D6: Revisado por: | G6: XX-XX
A7: Supervisado por: | D7: Aprobado por:
A10: OBJETIVO
A11: Esta herramienta permite evaluar y asegurar el estado actual de la implementación, mantenimiento y mejora del sistema de gestión de la seguridad de la información (SGSI) según la norma ISO 27001:2022, y determinar si está integrado y aplicado de manera efectiva en la organización. Esto incluye verificar que la seguridad de la información está gestionada de forma sistemática, adaptada a las necesidades organizacionales, y en mejora continua.
A12: ALCANCE
A13: La operación es un aspecto crucial en la implementación y mantenimiento de un sistema de gestión de la seguridad de la información (SGSI) conforme a la norma ISO 27001:2022. Este aspecto se enfoca en la planificación, ejecución y control de los procesos necesarios para asegurar que se cumplan los requisitos de seguridad de la información y que las acciones planificadas se implementen de manera efectiva.
A14: CHECKLIST ISO 27001 - OPERACIÓN
A15: 5.1 Planificación y control operativo: Para cumplir con los requisitos del SGSI y ejecutar las acciones determinadas, la organización debe planificar, implementar y controlar los procesos necesarios. Esto implica establecer criterios para los procesos y asegurar que estos se lleven a cabo de acuerdo con los criterios establecidos. Además, la organización debe gestionar los cambios planificados y revisar las consecuencias de los cambios no deseados, tomando medidas para mitigar cualquier efecto adverso. | G15: =IF(COUNTIF(G17:G20,TRUE)>1,"SELECCIONE SOLAMENTE UN NIVEL","Marque la opción que describa mejor la situación actual de la operación del SGSI ") -> Marque la opción que describa mejor la situación actual de la operación del SGSI
A16: Nivel | B16: Detalle | D16: Descripción | F16: Características
A17: =+'Guía de uso'!$AA$7 -> Nivel 1 = Inicial | B17: No se planifican ni se controlan formalmente las operaciones relacionadas con la seguridad de la información. | D17: Las actividades operativas relacionadas con la seguridad son ad-hoc y no están documentadas, lo que resulta en una falta de coordinación y control. | F17: Falta de planificación y control formal. Actividades reactivas y no documentadas. | G17: FALSE | J17: =+IF(G17=TRUE,'Guía de uso'!$Y$7,0) -> 0
A18: =+'Guía de uso'!$AA$8 -> Nivel 2 = Repetible | B18: Se realizan esfuerzos básicos para planificar y controlar las operaciones, pero de manera inconsistente y dependiente de individuos específicos. | D18: Se ha comenzado a planificar y controlar las operaciones, pero la implementación es irregular y depende en gran medida de individuos específicos. | F18: Planificación básica e irregular. Dependencia de individuos específicos para el control. | G18: TRUE | J18: =+IF(G18=TRUE,'Guía de uso'!$Y$8,0) -> 2
A19: =+'Guía de uso'!$AA$9 -> Nivel 3 = Definido | B19: La planificación y el control operativo están bien documentados y definidos, siguiendo metodologías estándar con control básico. | D19: Las operaciones están claramente planificadas y controladas, siguiendo metodologías estándar, con un nivel básico de supervisión y control para asegurar su efectividad. | F19: Documentación clara y definición de procedimientos operativos. Uso de metodologías estándar. Control y supervisión básicos. | G19: FALSE | J19: =+IF(G19=TRUE,'Guía de uso'!$Y$9,0) -> 0
A20: =+'Guía de uso'!$AA$10 -> Nivel 4 = Gestionado | B20: La planificación y el control operativo están completamente integrados en los procesos, con supervisión regular y uso de métricas para evaluar su efectividad. | D20: La planificación y el control operativo están integrados en los procesos organizacionales, con monitoreo continuo y uso de métricas y KPIs para asegurar la efectividad y mejora. | F20: Integración completa de la planificación y el control operativo en los procesos. Supervisión y control regulares. Uso de métricas y KPIs para evaluar la efectividad operativa. | G20: FALSE | J20: =+IF(G20=TRUE,'Guía de uso'!$Y$10,0) -> 0
A21: 5.2 Evaluación de riesgos de Seguridad de la Información: La organización debe realizar evaluaciones de riesgos de seguridad de la información a intervalos planificados o cuando se proponen o ocurren cambios significativos. Estas evaluaciones deben basarse en los criterios establecidos y documentarse adecuadamente. La evaluación regular de los riesgos permite a la organización identificar y mitigar nuevas amenazas de manera oportuna, manteniendo la integridad, confidencialidad y disponibilidad de la información. | G21: =IF(COUNTIF(G23:G26,TRUE)>1,"SELECCIONE SOLAMENTE UN NIVEL","Marque la opción que describa mejor la situación actual de la operación del SGSI ") -> Marque la opción que describa mejor la situación actual de la operación del SGSI
A22: Nivel | B22: Detalle | D22: Descripción | F22: Características
A23: =+'Guía de uso'!$AA$7 -> Nivel 1 = Inicial | B23: No se realizan evaluaciones formales de riesgos de seguridad de la información. | D23: Las evaluaciones de riesgos son esporádicas y no están documentadas, lo que resulta en una falta de identificación y evaluación sistemática de los riesgos. | F23: Ausencia de evaluaciones formales. Evaluaciones esporádicas y no documentadas. Falta de identificación sistemática de riesgos. | G23: FALSE | J23: =+IF(G23=TRUE,'Guía de uso'!$Y$7,0) -> 0
A24: =+'Guía de uso'!$AA$8 -> Nivel 2 = Repetible | B24: Se realizan esfuerzos básicos para evaluar los riesgos, pero de manera inconsistente y dependiente de individuos específicos. | D24: Se han comenzado a evaluar los riesgos, pero la implementación es irregular y depende de individuos específicos para su efectividad. | F24: Evaluación básica e irregular de riesgos. Dependencia de individuos específicos para la evaluación. | G24: TRUE | J24: =+IF(G24=TRUE,'Guía de uso'!$Y$8,0) -> 2
A25: =+'Guía de uso'!$AA$9 -> Nivel 3 = Definido | B25: Los procesos de evaluación de riesgos están bien documentados y definidos, siguiendo metodologías estándar con control básico. | D25: Los procesos de evaluación de riesgos están claramente documentados y definidos, siguiendo metodologías estándar, con un nivel básico de control y supervisión. | F25: Procesos bien documentados y definidos. Uso de metodologías estándar. Control y supervisión básicos. | G25: FALSE | J25: =+IF(G25=TRUE,'Guía de uso'!$Y$9,0) -> 0
A26: =+'Guía de uso'!$AA$10 -> Nivel 4 = Gestionado | B26: La evaluación de riesgos está completamente integrada en los procesos, con supervisión regular y uso de métricas para evaluar su efectividad. | D26: La evaluación de riesgos está integrada en los procesos organizacionales, con monitoreo continuo y uso de métricas y KPIs para asegurar la efectividad y mejora. | F26: Integración completa en los procesos. Supervisión y control regulares. Uso de métricas y KPIs para evaluar la efectividad de la evaluación de riesgos. | G26: FALSE | J26: =+IF(G26=TRUE,'Guía de uso'!$Y$10,0) -> 0
A27: 5.3 Tratamiento de riesgos de Seguridad de la Información: Implementar el plan de tratamiento de riesgos es fundamental para gestionar eficazmente los riesgos identificados. La organización debe asegurarse de que las acciones de tratamiento de riesgos se lleven a cabo y que se conserven registros documentados de los resultados. Este proceso implica seleccionar las medidas de control adecuadas para mitigar los riesgos y asegurar que estas se implementen de manera efectiva. | G27: =IF(COUNTIF(G29:G32,TRUE)>1,"SELECCIONE SOLAMENTE UN NIVEL","Marque la opción que describa mejor la situación actual de la operación del SGSI ") -> Marque la opción que describa mejor la situación actual de la operación del SGSI
A28: Nivel | B28: Detalle | D28: Descripción | F28: Características
A29: =+'Guía de uso'!$AA$7 -> Nivel 1 = Inicial | B29: No se toman acciones formales para el tratamiento de riesgos de seguridad de la información. | D29: Las acciones relacionadas con el tratamiento de riesgos son ad-hoc y no están documentadas, resultando en una falta de mitigación sistemática de los riesgos. | F29: Ausencia de acciones formales. Actividades reactivas y no documentadas. Falta de proceso sistemático para mitigar riesgos. | G29: FALSE | J29: =+IF(G29=TRUE,'Guía de uso'!$Y$7,0) -> 0
A30: =+'Guía de uso'!$AA$8 -> Nivel 2 = Repetible | B30: Se realizan esfuerzos básicos para tratar los riesgos, pero de manera inconsistente y dependiente de individuos específicos. | D30: Se han documentado acciones para el tratamiento de riesgos, pero la implementación es irregular y depende de individuos específicos para su efectividad. | F30: Tratamiento básico e irregular de riesgos. Dependencia de individuos específicos para la mitigación. | G30: TRUE | J30: =+IF(G30=TRUE,'Guía de uso'!$Y$8,0) -> 2
